Workbook
Name Hedging_Positions_through_Futures_AS_ON_MMMM_DD__YYYY___NIL: EDBE23!#REF!
Name Hedging_Positions_through_Futures_AS_ON_MMMM_DD__YYYY___NIL: EDBE25!#REF!
Name Hedging_Positions_through_Futures_AS_ON_MMMM_DD__YYYY___NIL: EDBE30!#REF!
Name Hedging_Positions_through_Futures_AS_ON_MMMM_DD__YYYY___NIL: EDBE31!#REF!
Name Hedging_Positions_through_Futures_AS_ON_MMMM_DD__YYYY___NIL: EDBE32!#REF!
Name Hedging_Positions_through_Futures_AS_ON_MMMM_DD__YYYY___NIL: EDBPDF!#REF!
Name Hedging_Positions_through_Futures_AS_ON_MMMM_DD__YYYY___NIL: EDCG27!#REF!
Name Hedging_Positions_through_Futures_AS_ON_MMMM_DD__YYYY___NIL: EDCG37!#REF!
Name Hedging_Positions_through_Futures_AS_ON_MMMM_DD__YYYY___NIL: EDCPSF!#REF!
Name Hedging_Positions_through_Futures_AS_ON_MMMM_DD__YYYY___NIL: EDFF23!#REF!
Name Hedging_Positions_through_Futures_AS_ON_MMMM_DD__YYYY___NIL: EDFF25!#REF!
Name Hedging_Positions_through_Futures_AS_ON_MMMM_DD__YYYY___NIL: EDFF30!#REF!
Name Hedging_Positions_through_Futures_AS_ON_MMMM_DD__YYYY___NIL: EDFF31!#REF!
Name Hedging_Positions_through_Futures_AS_ON_MMMM_DD__YYYY___NIL: EDFF32!#REF!
Name Hedging_Positions_through_Futures_AS_ON_MMMM_DD__YYYY___NIL: EDGSEC!#REF!
Name Hedging_Positions_through_Futures_AS_ON_MMMM_DD__YYYY___NIL: EDNP27!#REF!
Name Hedging_Positions_through_Futures_AS_ON_MMMM_DD__YYYY___NIL: EDNPSF!#REF!
Name Hedging_Positions_through_Futures_AS_ON_MMMM_DD__YYYY___NIL: EDONTF!#REF!
Name Hedging_Positions_through_Futures_AS_ON_MMMM_DD__YYYY___NIL: EEARBF!#REF!
Name Hedging_Positions_through_Futures_AS_ON_MMMM_DD__YYYY___NIL: EEARFD!#REF!
Name Hedging_Positions_through_Futures_AS_ON_MMMM_DD__YYYY___NIL: EEDGEF!#REF!
Name Hedging_Positions_through_Futures_AS_ON_MMMM_DD__YYYY___NIL: EEECRF!#REF!
Name Hedging_Positions_through_Futures_AS_ON_MMMM_DD__YYYY___NIL: EEELSS!#REF!
Name Hedging_Positions_through_Futures_AS_ON_MMMM_DD__YYYY___NIL: EEEQTF!#REF!
Name Hedging_Positions_through_Futures_AS_ON_MMMM_DD__YYYY___NIL: EEESCF!#REF!
Name Hedging_Positions_through_Futures_AS_ON_MMMM_DD__YYYY___NIL: EEESSF!#REF!
Name Hedging_Positions_through_Futures_AS_ON_MMMM_DD__YYYY___NIL: EEFOCF!#REF!
Name Hedging_Positions_through_Futures_AS_ON_MMMM_DD__YYYY___NIL: EEIF30!#REF!
Name Hedging_Positions_through_Futures_AS_ON_MMMM_DD__YYYY___NIL: EEIF50!#REF!
Name Hedging_Positions_through_Futures_AS_ON_MMMM_DD__YYYY___NIL: EELMIF!#REF!
Name Hedging_Positions_through_Futures_AS_ON_MMMM_DD__YYYY___NIL: EEMOF1!#REF!
Name Hedging_Positions_through_Futures_AS_ON_MMMM_DD__YYYY___NIL: EENFBA!#REF!
Name Hedging_Positions_through_Futures_AS_ON_MMMM_DD__YYYY___NIL: EEPRUA!#REF!
Name Hedging_Positions_through_Futures_AS_ON_MMMM_DD__YYYY___NIL: EESMCF!#REF!
Name Hedging_Positions_through_Futures_AS_ON_MMMM_DD__YYYY___NIL: EGSFOF!#REF!
Name Hedging_Positions_through_Futures_AS_ON_MMMM_DD__YYYY___NIL: ELLIQF!#REF!
Name Hedging_Positions_through_Futures_AS_ON_MMMM_DD__YYYY___NIL: EOASEF!#REF!
Name Hedging_Positions_through_Futures_AS_ON_MMMM_DD__YYYY___NIL: EOCHIF!#REF!
Name Hedging_Positions_through_Futures_AS_ON_MMMM_DD__YYYY___NIL: EODWHF!#REF!
Name Hedging_Positions_through_Futures_AS_ON_MMMM_DD__YYYY___NIL: EOEDOF!#REF!
Name Hedging_Positions_through_Futures_AS_ON_MMMM_DD__YYYY___NIL: EOEMOP!#REF!
Name Hedging_Positions_through_Futures_AS_ON_MMMM_DD__YYYY___NIL: EOUSEF!#REF!
Name Hedging_Positions_through_Futures_AS_ON_MMMM_DD__YYYY___NIL: EOUSTF!#REF!
Name Hedging_Positions_through_Futures_AS_ON_MMMM_DD__YYYY___NIL: EDACBF!#REF!
Name JPM_Footer_disp: EDBE23!#REF!
Name JPM_Footer_disp: EDBE25!#REF!
Name JPM_Footer_disp: EDBE30!#REF!
Name JPM_Footer_disp: EDBE31!#REF!
Name JPM_Footer_disp: EDBE32!#REF!
Name JPM_Footer_disp: EDBPDF!#REF!
Name JPM_Footer_disp: EDCG27!#REF!
Name JPM_Footer_disp: EDCG37!#REF!
Name JPM_Footer_disp: EDCPSF!#REF!
Name JPM_Footer_disp: EDFF23!#REF!
Name JPM_Footer_disp: EDFF25!#REF!
Name JPM_Footer_disp: EDFF30!#REF!
Name JPM_Footer_disp: EDFF31!#REF!
Name JPM_Footer_disp: EDFF32!#REF!
Name JPM_Footer_disp: EDGSEC!#REF!
Name JPM_Footer_disp: EDNP27!#REF!

Sheet Index
A1: EDELWEISS MUTUAL FUND
A2: PORTFOLIO STATEMENT as on 31 Oct 02022
A3: Fund Id | B3: Fund Desc | C3: Scheme Risk- O - Meter | D3: Benchmark of the Scheme | E3: Benchmark Risk-o-meter | F3: Benchmark of the Scheme | G3: Benchmark Risk-o-meter
A4: EDACBF | B4: =HYPERLINK("[EDEL_Portfolio Monthly Notes 31-Oct-2022.xlsx]EDACBF!A1","Edelweiss Money Market Fund") -> Edelweiss Money Market Fund | D4: NIFTY Money Market Index B-I (TIER-1) | F4: NIFTY Money Market Index A-I (TIER-2)
A5: EDBE23 | B5: =HYPERLINK("[EDEL_Portfolio Monthly Notes 31-Oct-2022.xlsx]EDBE23!A1","BHARAT Bond ETF - April 2023") -> BHARAT Bond ETF - April 2023 | D5: NIFTY BHARAT Bond Index - April 2023
A6: EDBE25 | B6: =HYPERLINK("[EDEL_Portfolio Monthly Notes 31-Oct-2022.xlsx]EDBE25!A1","BHARAT Bond ETF - April 2025") -> BHARAT Bond ETF - April 2025 | D6: NIFTY BHARAT Bond Index - April 2025
A7: EDBE30 | B7: =HYPERLINK("[EDEL_Portfolio Monthly Notes 31-Oct-2022.xlsx]EDBE30!A1","BHARAT Bond ETF - April 2030") -> BHARAT Bond ETF - April 2030 | D7: NIFTY BHARAT Bond Index - April 2030
A8: EDBE31 | B8: =HYPERLINK("[EDEL_Portfolio Monthly Notes 31-Oct-2022.xlsx]EDBE31!A1","BHARAT Bond ETF - April 2031") -> BHARAT Bond ETF - April 2031 | D8: NIFTY BHARAT Bond Index - April 2031
A9: EDBE32 | B9: =HYPERLINK("[EDEL_Portfolio Monthly Notes 31-Oct-2022.xlsx]EDBE32!A1","BHARAT Bond ETF - April 2032") -> BHARAT Bond ETF - April 2032 | D9: Nifty BHARAT Bond Index – April 2032
A10: EDBPDF | B10: =HYPERLINK("[EDEL_Portfolio Monthly Notes 31-Oct-2022.xlsx]EDBPDF!A1","Edelweiss Banking and PSU Debt Fund") -> Edelweiss Banking and PSU Debt Fund | D10: NIFTY Banking and PSU Debt Index (TIER - 1) | F10: Nifty Banking & PSU Debt Index - A-III (TIER - 2)
A11: EDCG27 | B11: =HYPERLINK("[EDEL_Portfolio Monthly Notes 31-Oct-2022.xlsx]EDCG27!A1","Edelweiss CRISIL IBX 50 50 Gilt Plus SDL June 2027 Index Fund") -> Edelweiss CRISIL IBX 50 50 Gilt Plus SDL June 2027 Index Fund | D11: (CRISIL IBX 50:50 Gilt Plus SDL Index – June 2027
A12: EDCG37 | B12: =HYPERLINK("[EDEL_Portfolio Monthly Notes 31-Oct-2022.xlsx]EDCG37!A1","Edelweiss_CRISIL IBX 50 50 Gilt Plus SDL April 2037 Index Fund") -> Edelweiss_CRISIL IBX 50 50 Gilt Plus SDL April 2037 Index Fund | D12: CRISIL IBX 50:50 Gilt Plus SDL Index – April 2037
A13: EDCPSF | B13: =HYPERLINK("[EDEL_Portfolio Monthly Notes 31-Oct-2022.xlsx]EDCPSF!A1","Edelweiss CRL PSU PL SDL 50 50 Oct-25 FD") -> Edelweiss CRL PSU PL SDL 50 50 Oct-25 FD | D13: CRISIL [IBX] 50:50 PSU + SDL Index - October 2025
A14: EDFF23 | B14: =HYPERLINK("[EDEL_Portfolio Monthly Notes 31-Oct-2022.xlsx]EDFF23!A1","BHARAT Bond FOF - April 2023") -> BHARAT Bond FOF - April 2023 | D14: NIFTY BHARAT Bond Index - April 2023
A15: EDFF25 | B15: =HYPERLINK("[EDEL_Portfolio Monthly Notes 31-Oct-2022.xlsx]EDFF25!A1","BHARAT Bond FOF - April 2025") -> BHARAT Bond FOF - April 2025 | D15: Nifty BHARAT Bond Index – April 2025
A16: EDFF30 | B16: =HYPERLINK("[EDEL_Portfolio Monthly Notes 31-Oct-2022.xlsx]EDFF30!A1","BHARAT Bond FOF - April 2030") -> BHARAT Bond FOF - April 2030 | D16: NIFTY BHARAT Bond Index - April 2030
A17: EDFF31 | B17: =HYPERLINK("[EDEL_Portfolio Monthly Notes 31-Oct-2022.xlsx]EDFF31!A1","BHARAT Bond FOF - April 2031") -> BHARAT Bond FOF - April 2031 | D17: NIFTY BHARAT Bond Index - April 2031
A18: EDFF32 | B18: =HYPERLINK("[EDEL_Portfolio Monthly Notes 31-Oct-2022.xlsx]EDFF32!A1","BHARAT Bond FOF - April 2032") -> BHARAT Bond FOF - April 2032 | D18: Nifty BHARAT Bond Index – April 2032
A19: EDGSEC | B19: =HYPERLINK("[EDEL_Portfolio Monthly Notes 31-Oct-2022.xlsx]EDGSEC!A1","Edelweiss Government Securities Fund") -> Edelweiss Government Securities Fund | D19: NIFTY All Duration G-Sec Index (TIER - 1) | F19: Nifty G -Sec Index A -III (TIER - 2)
A20: EDNP27 | B20: =HYPERLINK("[EDEL_Portfolio Monthly Notes 31-Oct-2022.xlsx]EDNP27!A1","Edelweiss Nifty PSU Bond Plus SDL Apr2027 50 50 Index") -> Edelweiss Nifty PSU Bond Plus SDL Apr2027 50 50 Index | D20: Nifty PSU Bond Plus SDL Apr 2027 50:50 Index
A21: EDNPSF | B21: =HYPERLINK("[EDEL_Portfolio Monthly Notes 31-Oct-2022.xlsx]EDNPSF!A1","Edelweiss Nifty PSU Bond Plus SDL Apr2026 50 50 Index Fund") -> Edelweiss Nifty PSU Bond Plus SDL Apr2026 50 50 Index Fund | D21: Nifty PSU Bond Plus SDL Apr 2026 50:50 Index
A22: EDONTF | B22: =HYPERLINK("[EDEL_Portfolio Monthly Notes 31-Oct-2022.xlsx]EDONTF!A1","EDELWEISS OVERNIGHT FUND") -> EDELWEISS OVERNIGHT FUND | D22: NIFTY 1D Rate Index
A23: EEARBF | B23: =HYPERLINK("[EDEL_Portfolio Monthly Notes 31-Oct-2022.xlsx]EEARBF!A1","Edelweiss Arbitrage Fund") -> Edelweiss Arbitrage Fund | D23: Nifty 50 Arbitrage PR Index
A24: EEARFD | B24: =HYPERLINK("[EDEL_Portfolio Monthly Notes 31-Oct-2022.xlsx]EEARFD!A1","Edelweiss Balanced Advantage Fund") -> Edelweiss Balanced Advantage Fund | D24: NIFTY 50 Hybrid Composite debt 50:50 Index
A25: EEDGEF | B25: =HYPERLINK("[EDEL_Portfolio Monthly Notes 31-Oct-2022.xlsx]EEDGEF!A1","Edelweiss Large Cap Fund") -> Edelweiss Large Cap Fund | D25: Nifty 100 TRI
A26: EEECRF | B26: =HYPERLINK("[EDEL_Portfolio Monthly Notes 31-Oct-2022.xlsx]EEECRF!A1","Edelweiss Flexi-Cap Fund") -> Edelweiss Flexi-Cap Fund | D26: Nifty 500 Total Return Index
A27: EEELSS | B27: =HYPERLINK("[EDEL_Portfolio Monthly Notes 31-Oct-2022.xlsx]EEELSS!A1","Edelweiss Long Term Equity Fund") -> Edelweiss Long Term Equity Fund | D27: Nifty 500 Total Return Index
A28: EEEQTF | B28: =HYPERLINK("[EDEL_Portfolio Monthly Notes 31-Oct-2022.xlsx]EEEQTF!A1","Edelweiss Large & Mid Cap Fund") -> Edelweiss Large & Mid Cap Fund | D28: Nifty Large Midcap 250 Index - Total Return Index
A29: EEESCF | B29: =HYPERLINK("[EDEL_Portfolio Monthly Notes 31-Oct-2022.xlsx]EEESCF!A1","Edelweiss Small Cap Fund") -> Edelweiss Small Cap Fund | D29: Nifty Smallcap 250 TR Index
A30: EEESSF | B30: =HYPERLINK("[EDEL_Portfolio Monthly Notes 31-Oct-2022.xlsx]EEESSF!A1","Edelweiss Equity Savings Fund") -> Edelweiss Equity Savings Fund | D30: NIFTY Equity Savings Index
A31: EEFOCF | B31: =HYPERLINK("[EDEL_Portfolio Monthly Notes 31-Oct-2022.xlsx]EEFOCF!A1","Edelweiss Focused Equity Fund") -> Edelweiss Focused Equity Fund | D31: NIFTY 500 Total Return Index
A32: EEIF30 | B32: =HYPERLINK("[EDEL_Portfolio Monthly Notes 31-Oct-2022.xlsx]EEIF30!A1","Edelweiss Nifty 100 Quality 30 Index Fnd") -> Edelweiss Nifty 100 Quality 30 Index Fnd | D32: Nifty 100 Quality 30 TRI
A33: EEIF50 | B33: =HYPERLINK("[EDEL_Portfolio Monthly Notes 31-Oct-2022.xlsx]EEIF50!A1","Edelweiss Nifty 50 Index Fund") -> Edelweiss Nifty 50 Index Fund | D33: Nifty 50 TRI
A34: EELMIF | B34: =HYPERLINK("[EDEL_Portfolio Monthly Notes 31-Oct-2022.xlsx]EELMIF!A1","Edelweiss NIFTY Large Mid Cap 250 Index Fund") -> Edelweiss NIFTY Large Mid Cap 250 Index Fund | D34: NIFTY LargeMidcap 250 Index Total Return Index
A35: EEMOF1 | B35: =HYPERLINK("[EDEL_Portfolio Monthly Notes 31-Oct-2022.xlsx]EEMOF1!A1","EDELWEISS RECENTLY LISTED IPO FUND") -> EDELWEISS RECENTLY LISTED IPO FUND | D35: India Recent 100 IPO Index TRI
A36: EENFBA | B36: =HYPERLINK("[EDEL_Portfolio Monthly Notes 31-Oct-2022.xlsx]EENFBA!A1","Edelweiss ETF - Nifty Bank") -> Edelweiss ETF - Nifty Bank | D36: Nifty Bank TRI
A37: EEPRUA | B37: =HYPERLINK("[EDEL_Portfolio Monthly Notes 31-Oct-2022.xlsx]EEPRUA!A1","Edelweiss Aggressive Hybrid Fund") -> Edelweiss Aggressive Hybrid Fund | D37: CRISIL Hybrid 35+65 - Aggressive Index
A38: EESMCF | B38: =HYPERLINK("[EDEL_Portfolio Monthly Notes 31-Oct-2022.xlsx]EESMCF!A1","Edelweiss Mid Cap Fund") -> Edelweiss Mid Cap Fund | D38: Nifty Midcap 150 Total Return Index
A39: EGSFOF | B39: =HYPERLINK("[EDEL_Portfolio Monthly Notes 31-Oct-2022.xlsx]EGSFOF!A1","Edelweiss Gold and Silver ETF FOF") -> Edelweiss Gold and Silver ETF FOF | D39: LBMA Prices
A40: ELLIQF | B40: =HYPERLINK("[EDEL_Portfolio Monthly Notes 31-Oct-2022.xlsx]ELLIQF!A1","Edelweiss Liquid Fund") -> Edelweiss Liquid Fund | D40: NIFTY Liquid Index B-I (TIER-1) | F40: NIFTY Liquid Index A-I (TIER-2)
...

Sheet EDACBF
A1: PORTFOLIO STATEMENT OF EDELWEISS MONEY MARKET FUND AS ON OCTOBER 31, 2022 | H1: =HYPERLINK("[EDEL_Portfolio Monthly Notes 31-Oct-2022.xlsx]Index!A1","Index") -> Index
A2: (An open-ended debt scheme investing in money market instruments)
A4: Name of the Instrument | B4: ISIN | C4: Rating/Industry | D4: Quantity | E4: Market/Fair Value(Rs. In Lacs) | F4: % to Net Assets | G4: YIELD
A7: Equity & Equity related | E7: NIL | F7: NIL
A9: Money Market Instruments
A11: Treasury bills
A12: 364 DAYS TBILL RED 20-07-2023 | B12: IN002022Z168 | C12: SOVEREIGN | D12: 2500000 | E12: 2383.1 | F12: 0.0732 | G12: 0.0686
A13: Sub Total | E13: 2383.1 | F13: 0.0732
A14: Certificate of Deposit
A15: SIDBI CD RED 30-05-2023#** | B15: INE556F16960 | C15: CRISIL A1+ | D15: 2500000 | E15: 2399.04 | F15: 0.0737 | G15: 0.07315
A16: EXIM BANK CD RED 22-06-2023#** | B16: INE514E16CB6 | C16: CRISIL A1+ | D16: 2500000 | E16: 2388.4 | F16: 0.0734 | G16: 0.0732
A17: BANK OF BARODA CD RED 17-08-2023#** | B17: INE028A16CT7 | C17: ICRA A1+ | D17: 2500000 | E17: 2360.48 | F17: 0.0725 | G17: 0.07465
A18: CANARA BANK CD RED 18-08-2023#** | B18: INE476A16TV8 | C18: CRISIL A1+ | D18: 2500000 | E18: 2360.11 | F18: 0.0725 | G18: 0.0746
A19: KOTAK MAHINDRA BANK CD RED 17-08-2023#** | B19: INE237A169P8 | C19: CRISIL A1+ | D19: 2500000 | E19: 2359.84 | F19: 0.0725 | G19: 0.075016
A20: IDFC FIRST BANK LTD. CD RED 24-08-2023#** | B20: INE092T16SS1 | C20: CRISIL A1+ | D20: 2500000 | E20: 2353.52 | F20: 0.0723 | G20: 0.07675
A21: STATE BK OF INDIA CD 12-09-23#** | B21: INE062A16465 | C21: ICRA A1+ | D21: 2500000 | E21: 2350.69 | F21: 0.0722 | G21: 0.0736
A22: AXIS BANK LTD CD RED 07-09-2023#** | B22: INE238AD6025 | C22: CRISIL A1+ | D22: 2500000 | E22: 2348.98 | F22: 0.0722 | G22: 0.0757
A23: HDFC BANK CD RED 12-09-2023#** | B23: INE040A16DK9 | C23: CARE A1+ | D23: 2500000 | E23: 2347.07 | F23: 0.0721 | G23: 0.0755
A24: Sub Total | E24: 21268.13 | F24: 0.6534
A26: Commercial Paper
A27: LIC HSG FIN CP RED 20-06-2023** | B27: INE115A14DT5 | C27: CRISIL A1+ | D27: 2500000 | E27: 2386.57 | F27: 0.0733 | G27: 0.0751
A28: HDFC LTD CP RED 25-07-2023** | B28: INE001A14ZE2 | C28: CRISIL A1+ | D28: 2500000 | E28: 2368.48 | F28: 0.0728 | G28: 0.076199
A29: RELIANCE JIO INFO LTD CP 29-09-23** | B29: INE110L14RD7 | C29: CRISIL A1+ | D29: 2500000 | E29: 2336.47 | F29: 0.0718 | G29: 0.07695
A30: Sub Total | E30: 7091.52 | F30: 0.2179
A32: TOTAL | E32: 30742.75 | F32: 0.9445
A35: TREPS / Reverse Repo
A36: Clearing Corporation of India Ltd. | E36: 1926.68 | F36: 0.0592 | G36: 0.061074
A37: Sub Total | E37: 1926.68 | F37: 0.0592
A39: TOTAL | E39: 1926.68 | F39: 0.0592
A40: Accrued Interest | E40: 0.3223833 | F40: 9e-06
A41: Net Receivables/(Payables) | E41: -114.54238 | F41: -0.003709 | G41: 0.061074
A42: GRAND TOTAL | E42: 32555.21 | F42: 1
A44: # Unlisted Security
A45: **Non Traded Security
A47: Notes:
A48: 1. Security in default beyond its maturiy date | B48: NIL
A49: 2. NAV at the beginning of the period (Rs. per unit)
A50: Plan /option (Face Value 10) | B50: As on | C50: As on
B51: 44834 | C51: 44865
A52: Direct Plan Annual IDCW Option | B52: 25.7044 | C52: 25.7848
...

Sheet EDBE23
A1: PORTFOLIO STATEMENT OF BHARAT BOND ETF – APRIL 2023 AS ON OCTOBER 31, 2022 | H1: =HYPERLINK("[EDEL_Portfolio Monthly Notes 31-Oct-2022.xlsx]Index!A1","Index") -> Index
A2: (An open ended Target Maturity Exchange Traded Bond Fund predominately investing in constituents of Nifty BHARAT Bond Index - April 2023)
A4: Name of the Instrument | B4: ISIN | C4: Rating/Industry | D4: Quantity | E4: Market/Fair Value(Rs. In Lacs) | F4: % to Net Assets | G4: YIELD
A7: Equity & Equity related | E7: NIL | F7: NIL
A9: Debt Instruments
A10: (a)Listed / Awaiting listing on stock Exchanges
A11: 6.59% IRFC NCD RED 14-04-2023** | B11: INE053F07BZ2 | C11: CRISIL AAA | D11: 100500000 | E11: 100177.6 | F11: 0.1475 | G11: 0.07305
A12: 6.44% INDIAN OIL CORP NCD RED 14-04-2023** | B12: INE242A08445 | C12: CRISIL AAA | D12: 77000000 | E12: 76726.73 | F12: 0.1129 | G12: 0.0728
A13: 7.04% PFC LTD NCD RED 14-04-2023** | B13: INE134E08KJ6 | C13: CRISIL AAA | D13: 70000000 | E13: 69915.37 | F13: 0.1029 | G13: 0.07345
A14: 6.79% HUDCO NCD RED 14-04-2023** | B14: INE031A08764 | C14: ICRA AAA | D14: 68000000 | E14: 67857.47 | F14: 0.0999 | G14: 0.07285
A15: 6.72% NABARD NCD RED 14-04-2023** | B15: INE261F08BW6 | C15: ICRA AAA | D15: 64300000 | E15: 64065.05 | F15: 0.0943 | G15: 0.072901
A16: 7.12% REC LTD. NCD RED 31-03-2023** | B16: INE020B08CH4 | C16: CRISIL AAA | D16: 44000000 | E16: 43935.67 | F16: 0.0647 | G16: 0.07185
A17: 6.38% HPCL NCD RED 12-04-2023** | B17: INE094A08051 | C17: CRISIL AAA | D17: 36500000 | E17: 36364.48 | F17: 0.0535 | G17: 0.07245
A18: 8.82% REC LTD NCD RED 12-04-23** | B18: INE020B08831 | C18: CARE AAA | D18: 33000000 | E18: 33158.1 | F18: 0.0488 | G18: 0.073451
A19: 6.64% MANGALORE REF & PET NCD 14-04-2023** | B19: INE103A08027 | C19: CRISIL AAA | D19: 26000000 | E19: 25915.24 | F19: 0.0381 | G19: 0.07415
A20: 8.8% POWER GRID CORP NCD RED 13-03-2023** | B20: INE752E07KN9 | C20: CRISIL AAA | D20: 22500000 | E20: 22600.71 | F20: 0.0333 | G20: 0.071299
A21: 8.5% NABARD NCD RED 31-01-2023 | B21: INE261F08AT4 | C21: CRISIL AAA | D21: 18000000 | E21: 18045.67 | F21: 0.0266 | G21: 0.070169
A22: 6.35% POWER GRID CORP NCD RED 14-04-2023** | B22: INE752E08627 | C22: CRISIL AAA | D22: 10000000 | E22: 9965.08 | F22: 0.0147 | G22: 0.07185
... A35: 8.9% POWER FIN CORP NCD RED 18-03-2023** | B35: INE134E08FN8 | C35: CRISIL AAA | D35: 500000 | E35: 502.45 | F35: 0.0007 | G35: 0.0716
A36: Sub Total | E36: 616867.1 | F36: 0.908
A38: (b)Privately Placed/Unlisted
A39: Sub Total | E39: NIL | F39: NIL
A41: (c)Securitised Debt Instruments
A42: Sub Total | E42: NIL | F42: NIL
A44: TOTAL | E44: 616867.1 | F44: 0.908
A46: Money Market Instruments
A47: Certificate of Deposit
A48: SIDBI CD RED 23-03-2023#** | B48: INE556F16952 | C48: CRISIL A1+ | D48: 12500000 | E48: 12166.78 | F48: 0.0179 | G48: 0.0704
A49: NABARD CD RED 08-02-2023# | B49: INE261F16637 | C49: CRISIL A1+ | D49: 10000000 | E49: 9812.72 | F49: 0.0144 | G49: 0.070365
A50: SIDBI CD RED 03-03-2023#** | B50: INE556F16945 | C50: CRISIL A1+ | D50: 10000000 | E50: 9770.1 | F50: 0.0144 | G50: 0.0704
A51: EXIM BANK CD RED 17-03-2023#** | B51: INE514E16BY0 | C51: CRISIL A1+ | D51: 5000000 | E51: 4872.64 | F51: 0.0072 | G51: 0.070151
A52: Sub Total | E52: 36622.24 | F52: 0.0539
A54: TOTAL | E54: 36622.24 | F54: 0.0539
A57: TREPS / Reverse Repo
A58: Clearing Corporation of India Ltd. | E58: 2708.55 | F58: 0.004 | G58: 0.061074
A59: Sub Total | E59: 2708.55 | F59: 0.004
A61: TOTAL | E61: 2708.55 | F61: 0.004
A62: Accrued Interest | E62: 25672.343 | F62: 0.037787
A63: Net Receivables/(Payables) | E63: -2485.4127 | F63: -0.003687 | G63: 0.061074
A64: GRAND TOTAL | E64: 679384.82 | F64: 1
...

Sheet EDBE25
A1: PORTFOLIO STATEMENT OF BHARAT BOND ETF – APRIL 2025 AS ON OCTOBER 31, 2022 | H1: =HYPERLINK("[EDEL_Portfolio Monthly Notes 31-Oct-2022.xlsx]Index!A1","Index") -> Index
A2: (An open ended Target Maturity Exchange Traded Bond Fund predominantly investing in constituents of Nifty BHARAT Bond Index - April 2025)
A4: Name of the Instrument | B4: ISIN | C4: Rating/Industry | D4: Quantity | E4: Market/Fair Value(Rs. In Lacs) | F4: % to Net Assets | G4: YIELD
A7: Equity & Equity related | E7: NIL | F7: NIL
A9: Debt Instruments
A10: (a)Listed / Awaiting listing on stock Exchanges
A11: 5.4% INDIAN OIL CORP NCD 11-04-25** | B11: INE242A08478 | C11: CRISIL AAA | D11: 85000000 | E11: 81121.11 | F11: 0.0807 | G11: 0.07515
A12: 5.36% HPCL NCD RED 11-04-2025** | B12: INE094A08077 | C12: CRISIL AAA | D12: 83500000 | E12: 79674.45 | F12: 0.0793 | G12: 0.074825
A13: 5.59% SIDBI NCD RED 21-02-2025** | B13: INE556F08JU6 | C13: CARE AAA | D13: 72500000 | E13: 69566.58 | F13: 0.0692 | G13: 0.07545
A14: 5.90% REC LTD. NCD RED 31-03-2025** | B14: INE020B08CZ6 | C14: CRISIL AAA | D14: 71500000 | E14: 68984.84 | F14: 0.0686 | G14: 0.0755
A15: 5.47% NABARD NCD RED 11-04-2025** | B15: INE261F08CI3 | C15: ICRA AAA | D15: 66500000 | E15: 63498.92 | F15: 0.0632 | G15: 0.0754
A16: 5.77% PFC LTD NCD RED 11-04-2025** | B16: INE134E08KX7 | C16: CRISIL AAA | D16: 65000000 | E16: 62502.96 | F16: 0.0622 | G16: 0.0755
A17: 5.23% NABARD NCD RED 31-01-2025** | B17: INE261F08DI1 | C17: CRISIL AAA | D17: 61000000 | E17: 58159.23 | F17: 0.0579 | G17: 0.0754
A18: 6.88% NHB LTD NCD RED 21-01-2025** | B18: INE557F08FH9 | C18: CRISIL AAA | D18: 55500000 | E18: 54855.03 | F18: 0.0546 | G18: 0.07445
A19: 5.35% HUDCO NCD RED 11-04-2025** | B19: INE031A08814 | C19: ICRA AAA | D19: 54000000 | E19: 51444.02 | F19: 0.0512 | G19: 0.07545
A20: 6.35% EXIM BANK OF INDIA NCD 18-02-2025** | B20: INE514E08FT8 | C20: CRISIL AAA | D20: 46000000 | E20: 44980.96 | F20: 0.0448 | G20: 0.0741
A21: 5.25% ONGC NCD RED 11-04-2025** | B21: INE213A08016 | C21: ICRA AAA | D21: 41500000 | E21: 39562.2 | F21: 0.0394 | G21: 0.0741
A22: 5.34% NLC INDIA LTD. NCD 11-04-25** | B22: INE589A08027 | C22: CRISIL AAA | D22: 39500000 | E22: 37666.53 | F22: 0.0375 | G22: 0.074898
... A60: 8.10% PFC LTD NCD RED 04-06-2024** | B60: INE134E08KD9 | C60: CRISIL AAA | D60: 500000 | E60: 503.62 | F60: 0.0005 | G60: 0.0755
A61: Sub Total | E61: 973790.02 | F61: 0.9687
A63: (b)Privately Placed/Unlisted
A64: Sub Total | E64: NIL | F64: NIL
A66: (c)Securitised Debt Instruments
A67: Sub Total | E67: NIL | F67: NIL
A69: TOTAL | E69: 973790.02 | F69: 0.9687
A72: TREPS / Reverse Repo
A73: Clearing Corporation of India Ltd. | E73: 6160.97 | F73: 0.0061 | G73: 0.061074
A74: Sub Total | E74: 6160.97 | F74: 0.0061
A76: TOTAL | E76: 6160.97 | F76: 0.0061
A77: Accrued Interest | E77: 29557.76 | F77: 0.029409
A78: Net Receivables/(Payables) | E78: -4471.2101 | F78: -0.004209 | G78: 0.061074
A79: GRAND TOTAL | E79: 1005037.5 | F79: 1
A81: **Non Traded Security
A84: Notes:
A85: 1. Security in default beyond its maturiy date | B85: NIL
A86: 2. NAV at the beginning of the period (Rs. per unit)
A87: Plan /option (Face Value 1000) | B87: As on | C87: As on
B88: 44834 | C88: 44865
A89: Growth Option | B89: 1078.3791 | C89: 1082.7518
A91: 3. Total Dividend (Net) declared during the month | B91: NIL
...

Sheet EDBE30
A1: PORTFOLIO STATEMENT OF BHARAT BOND ETF – APRIL 2030 AS ON OCTOBER 31, 2022 | H1: =HYPERLINK("[EDEL_Portfolio Monthly Notes 31-Oct-2022.xlsx]Index!A1","Index") -> Index
A2: (An open ended Target Maturity Exchange Traded Bond Fund predominately investing in constituents of Nifty BHARAT Bond Index - April 2030)
A4: Name of the Instrument | B4: ISIN | C4: Rating/Industry | D4: Quantity | E4: Market/Fair Value(Rs. In Lacs) | F4: % to Net Assets | G4: YIELD
A7: Equity & Equity related | E7: NIL | F7: NIL
A9: Debt Instruments
A10: (a)Listed / Awaiting listing on stock Exchanges
A11: 7.03% HPCL NCD RED 12-04-2030** | B11: INE094A08069 | C11: CRISIL AAA | D11: 97500000 | E11: 94001.02 | F11: 0.0647 | G11: 0.076724
A12: 7.41% POWER FIN CORP NCD RED 25-02-2030** | B12: INE134E08KL2 | C12: CRISIL AAA | D12: 89500000 | E12: 88179.34 | F12: 0.0606 | G12: 0.0767
A13: 7.89% REC LTD. NCD RED 30-03-2030** | B13: INE020B08CI2 | C13: CRISIL AAA | D13: 81000000 | E13: 81900.15 | F13: 0.0563 | G13: 0.07675
A14: 7.34% NPCIL NCD RED 23-01-2030** | B14: INE206D08469 | C14: ICRA AAA | D14: 83000000 | E14: 81548.99 | F14: 0.0561 | G14: 0.07655
A15: 7.55% IRFC NCD RED 12-04-2030** | B15: INE053F07BY5 | C15: CRISIL AAA | D15: 80500000 | E15: 80188.95 | F15: 0.0552 | G15: 0.07625
A16: 7.86% PFC LTD NCD RED 12-04-2030** | B16: INE134E08KK4 | C16: CRISIL AAA | D16: 75000000 | E16: 75773.48 | F16: 0.0521 | G16: 0.0767
A17: 7.54% NHAI NCD RED 25-01-2030** | B17: INE906B07HK9 | C17: CRISIL AAA | D17: 73000000 | E17: 72510.17 | F17: 0.0499 | G17: 0.07655
A18: 7.4% MANGALORE REF & PET NCD 12-04-2030** | B18: INE103A08019 | C18: CRISIL AAA | D18: 61500000 | E18: 60508.07 | F18: 0.0416 | G18: 0.076898
A19: 7.70% NHAI NCD RED 13-09-2029** | B19: INE906B07HH5 | C19: CRISIL AAA | D19: 54500000 | E19: 54652.16 | F19: 0.0376 | G19: 0.0764
A20: 7.41% IOC NCD RED 22-10-2029** | B20: INE242A08437 | C20: FITCH AAA | D20: 48000000 | E20: 47378.88 | F20: 0.0326 | G20: 0.07655
A21: 7.50% REC LTD. NCD RED 28-02-2030** | B21: INE020B08CP7 | C21: CRISIL AAA | D21: 41200000 | E21: 40781.86 | F21: 0.028 | G21: 0.07675
A22: 7.32% NTPC LTD NCD RED 17-07-2029** | B22: INE733E07KL3 | C22: CRISIL AAA | D22: 39500000 | E22: 38933.33 | F22: 0.0268 | G22: 0.0759
... A60: 8.4% POWER GRID NCD RED 26-05-2029** | B60: INE752E07MV8 | C60: CRISIL AAA | D60: 500000 | E60: 519.33 | F60: 0.0004 | G60: 0.07615
A61: Sub Total | E61: 1268743.7 | F61: 0.8727
A63: Government Securities
A64: 7.10% GOVT OF INDIA RED 18-04-2029 | B64: IN0020220011 | C64: SOVEREIGN | D64: 68500000 | E64: 67360.02 | F64: 0.0463 | G64: 0.07428
A65: 6.45% GOVT OF INDIA RED 07-10-2029 | B65: IN0020190362 | C65: SOVEREIGN | D65: 33000000 | E65: 31273.11 | F65: 0.0215 | G65: 0.074281
A66: 6.79% GOVT OF INDIA RED 26-12-2029 | B66: IN0020160118 | C66: SOVEREIGN | D66: 25500000 | E66: 24569.71 | F66: 0.0169 | G66: 0.074549
A67: 7.88% GOVT OF INDIA RED 19-03-2030 | B67: IN0020150028 | C67: SOVEREIGN | D67: 4000000 | E67: 4099.99 | F67: 0.0028 | G67: 0.074317
A68: Sub Total | E68: 127302.83 | F68: 0.0875
A70: (b)Privately Placed/Unlisted
A71: Sub Total | E71: NIL | F71: NIL
A73: (c)Securitised Debt Instruments
A74: Sub Total | E74: NIL | F74: NIL
A76: TOTAL | E76: 1396046.5 | F76: 0.9602
A79: TREPS / Reverse Repo
A80: Clearing Corporation of India Ltd. | E80: 8111.64 | F80: 0.0056 | G80: 0.061074
A81: Sub Total | E81: 8111.64 | F81: 0.0056
A83: TOTAL | E83: 8111.64 | F83: 0.0056
A84: Accrued Interest | E84: 49745.215 | F84: 0.034213
A85: Net Receivables/(Payables) | E85: 46.315332 | F85: -1.3e-05 | G85: 0.061074
A86: GRAND TOTAL | E86: 1453949.7 | F86: 1
A88: **Non Traded Security
A91: Notes:
...

Sheet EDBE31
A1: PORTFOLIO STATEMENT OF BHARAT BOND ETF – APRIL 2031 AS ON OCTOBER 31, 2022 | H1: =HYPERLINK("[EDEL_Portfolio Monthly Notes 31-Oct-2022.xlsx]Index!A1","Index") -> Index
A2: (An open ended Target Maturity Exchange Traded Bond Fund predominantly investing in constituents of Nifty BHARAT Bond Index - April 2031)
A4: Name of the Instrument | B4: ISIN | C4: Rating/Industry | D4: Quantity | E4: Market/Fair Value(Rs. In Lacs) | F4: % to Net Assets | G4: YIELD
A7: Equity & Equity related | E7: NIL | F7: NIL
A9: Debt Instruments
A10: (a)Listed / Awaiting listing on stock Exchanges
A11: 6.41% IRFC NCD RED 11-04-2031** | B11: INE053F07CR7 | C11: CRISIL AAA | D11: 102000000 | E11: 94253.1 | F11: 0.084 | G11: 0.07655
A12: 6.90% REC LTD. NCD RED 31-03-2031** | B12: INE020B08DA7 | C12: CRISIL AAA | D12: 97500000 | E12: 92780.9 | F12: 0.0827 | G12: 0.077
A13: 6.45% NABARD NCD RED 11-04-2031** | B13: INE261F08CJ1 | C13: ICRA AAA | D13: 100000000 | E13: 92329 | F13: 0.0823 | G13: 0.0771
A14: 6.50% NHAI NCD RED 11-04-2031** | B14: INE906B07IE0 | C14: CRISIL AAA | D14: 98500000 | E14: 91426.12 | F14: 0.0815 | G14: 0.07685
A15: 6.80% NPCL NCD RED 21-03-2031** | B15: INE206D08477 | C15: ICRA AAA | D15: 96000000 | E15: 90840.38 | F15: 0.081 | G15: 0.076833
A16: 6.88% PFC LTD NCD RED 11-04-2031** | B16: INE134E08KY5 | C16: CRISIL AAA | D16: 95500000 | E16: 90775.52 | F16: 0.0809 | G16: 0.07695
A17: 6.4% ONGC NCD RED 11-04-2031** | B17: INE213A08024 | C17: ICRA AAA | D17: 82000000 | E17: 76019.74 | F17: 0.0678 | G17: 0.075999
A18: 6.29% NTPC LTD NCD RED 11-04-2031** | B18: INE733E08155 | C18: CRISIL AAA | D18: 80000000 | E18: 73420.56 | F18: 0.0655 | G18: 0.07645
A19: 6.63% HPCL NCD RED 11-04-2031** | B19: INE094A08093 | C19: CRISIL AAA | D19: 71500000 | E19: 66787.79 | F19: 0.0596 | G19: 0.077123
A20: 6.65% FOOD CORP GOI GRNT NCD 23-10-2030** | B20: INE861G08076 | C20: ICRA AAA(CE) | D20: 67000000 | E20: 63028.17 | F20: 0.0562 | G20: 0.0767
A21: 6.28% POWER GRID CORP NCD 11-04-31** | B21: INE752E08650 | C21: CRISIL AAA | D21: 38500000 | E21: 35245.09 | F21: 0.0314 | G21: 0.07675
A22: 7.55% REC LTD. NCD RED 10-05-2030** | B22: INE020B08CU7 | C22: CRISIL AAA | D22: 24000000 | E22: 23816.66 | F22: 0.0212 | G22: 0.07675
... A38: 6.75% HUDCO NCD RED 29-05-2030** | B38: INE031A08806 | C38: ICRA AAA | D38: 500000 | E38: 473.59 | F38: 0.0004 | G38: 0.07685
A39: Sub Total | E39: 974293.05 | F39: 0.8688
A41: Government Securities
A42: 7.61% GOVT OF INDIA RED 09-05-2030 | B42: IN0020160019 | C42: SOVEREIGN | D42: 57000000 | E42: 57615.32 | F42: 0.0514 | G42: 0.074196
A43: 7.10% GOVT OF INDIA RED 18-04-2029 | B43: IN0020220011 | C43: SOVEREIGN | D43: 54000000 | E43: 53101.33 | F43: 0.0474 | G43: 0.07428
A44: Sub Total | E44: 110716.65 | F44: 0.0988
A46: (b)Privately Placed/Unlisted
A47: Sub Total | E47: NIL | F47: NIL
A49: (c)Securitised Debt Instruments
A50: Sub Total | E50: NIL | F50: NIL
A52: TOTAL | E52: 1085009.7 | F52: 0.9676
A55: TREPS / Reverse Repo
A56: Clearing Corporation of India Ltd. | E56: 9210.46 | F56: 0.0082 | G56: 0.061074
A57: Sub Total | E57: 9210.46 | F57: 0.0082
A59: TOTAL | E59: 9210.46 | F59: 0.0082
A60: Accrued Interest | E60: 27158.772 | F60: 0.024217
A61: Net Receivables/(Payables) | E61: 54.637718 | F61: -1.7e-05 | G61: 0.061074
A62: GRAND TOTAL | E62: 1121433.6 | F62: 1
A64: **Non Traded Security
A67: Notes:
A68: 1. Security in default beyond its maturiy date | B68: NIL
A69: 2. NAV at the beginning of the period (Rs. per unit)
...

Sheet EDBE32
A1: PORTFOLIO STATEMENT OF BHARAT BOND ETF – APRIL 2032 AS ON OCTOBER 31, 2022 | H1: =HYPERLINK("[EDEL_Portfolio Monthly Notes 31-Oct-2022.xlsx]Index!A1","Index") -> Index
A2: (An open ended Target Maturity Exchange Traded Bond Fund predominantly investing in constituents of Nifty BHARAT Bond Index - April 2032)
A4: Name of the Instrument | B4: ISIN | C4: Rating/Industry | D4: Quantity | E4: Market/Fair Value(Rs. In Lacs) | F4: % to Net Assets | G4: YIELD
A7: Equity & Equity related | E7: NIL | F7: NIL
A9: Debt Instruments
A10: (a)Listed / Awaiting listing on stock Exchanges
A11: 7.48% MANGALORE REF&PET 14-04-2032** | B11: INE103A08050 | C11: CARE AAA | D11: 83700000 | E11: 82379.63 | F11: 0.1062 | G11: 0.077198
A12: 6.74% NTPC LTD RED 14-04-2032** | B12: INE733E08205 | C12: CRISIL AAA | D12: 84500000 | E12: 79401.19 | F12: 0.1024 | G12: 0.0766
A13: 6.87% NHAI NCD RED 14-04-2032** | B13: INE906B07JA6 | C13: CRISIL AAA | D13: 82000000 | E13: 77620.05 | F13: 0.1001 | G13: 0.07685
A14: 6.92% POWER FINANCE NCD 14-04-32** | B14: INE134E08LN6 | C14: CRISIL AAA | D14: 80000000 | E14: 75938.72 | F14: 0.0979 | G14: 0.07695
A15: 6.92% REC LTD NCD RED 20-03-2032** | B15: INE020B08DV3 | C15: CRISIL AAA | D15: 80000000 | E15: 75888.48 | F15: 0.0978 | G15: 0.077
A16: 6.87% IRFC NCD RED 14-04-2032** | B16: INE053F08163 | C16: CRISIL AAA | D16: 75000000 | E16: 71154.68 | F16: 0.0917 | G16: 0.07655
A17: 7.79% IOC NCD RED 12-04-2032** | B17: INE242A08528 | C17: CRISIL AAA | D17: 50500000 | E17: 50691.55 | F17: 0.0654 | G17: 0.077249
A18: 6.85% NABARD NCD RED 14-04-2032** | B18: INE261F08DL5 | C18: CRISIL AAA | D18: 50000000 | E18: 47155.8 | F18: 0.0608 | G18: 0.0771
A19: 7.81% HPCL NCD RED 13-04-2032** | B19: INE094A08119 | C19: CRISIL AAA | D19: 39500000 | E19: 39734.47 | F19: 0.0512 | G19: 0.077123
A20: 6.85% NLC INDIA RED 13-04-2032** | B20: INE589A08043 | C20: CRISIL AAA | D20: 38000000 | E20: 35813.63 | F20: 0.0462 | G20: 0.0773
A21: 6.92% IRFC NCD SR 161 RED 29-08-2031** | B21: INE053F08122 | C21: CRISIL AAA | D21: 16500000 | E21: 15736.73 | F21: 0.0203 | G21: 0.07655
A22: 6.89% IRFC NCD RED 18-07-2031** | B22: INE053F08106 | C22: CRISIL AAA | D22: 14000000 | E22: 13331.58 | F22: 0.0172 | G22: 0.07655
... A26: 8.24% NHPC LTD SER U NCD RED 27-06-2031** | B26: INE848E07914 | C26: CARE AAA | D26: 1000000 | E26: 1032.53 | F26: 0.0013 | G26: 0.077
A27: Sub Total | E27: 686629.43 | F27: 0.8852
A29: Government Securities
A30: 6.54% GOVT OF INDIA RED 17-01-2032 | B30: IN0020210244 | C30: SOVEREIGN | D30: 51500000 | E30: 48307.15 | F30: 0.0623 | G30: 0.074812
A31: Sub Total | E31: 48307.15 | F31: 0.0623
A33: (b)Privately Placed/Unlisted
A34: Sub Total | E34: NIL | F34: NIL
A36: (c)Securitised Debt Instruments
A37: Sub Total | E37: NIL | F37: NIL
A39: TOTAL | E39: 734936.58 | F39: 0.9475
A42: TREPS / Reverse Repo
A43: Clearing Corporation of India Ltd. | E43: 8078.65 | F43: 0.0104 | G43: 0.061074
A44: Sub Total | E44: 8078.65 | F44: 0.0104
A46: TOTAL | E46: 8078.65 | F46: 0.0104
A47: Accrued Interest | E47: 32579.306 | F47: 0.042002
A48: Net Receivables/(Payables) | E48: 52.54425 | F48: 9.8e-05 | G48: 0.061074
A49: GRAND TOTAL | E49: 775647.08 | F49: 1
A51: **Non Traded Security
A54: Notes:
A55: 1. Security in default beyond its maturiy date | B55: NIL
A56: 2. NAV at the beginning of the period (Rs. per unit)
A57: Plan /option (Face Value 1000) | B57: As on | C57: As on
...

Sheet EDBPDF
A1: PORTFOLIO STATEMENT OF EDELWEISS BANKING AND PSU DEBT FUND AS ON OCTOBER 31, 2022 | H1: =HYPERLINK("[EDEL_Portfolio Monthly Notes 31-Oct-2022.xlsx]Index!A1","Index") -> Index
A2: (An open ended debt scheme predominantly investing in Debt Instruments of Banks, Public Sector Undertakings, Public Financial Institutions and Municipal Bonds.)
A4: Name of the Instrument | B4: ISIN | C4: Rating/Industry | D4: Quantity | E4: Market/Fair Value(Rs. In Lacs) | F4: % to Net Assets | G4: YIELD
A7: Equity & Equity related | E7: NIL | F7: NIL
A9: Debt Instruments
A10: (a)Listed / Awaiting listing on stock Exchanges
A11: 8.37% HUDCO NCD RED 23-03-2029** | B11: INE031A08707 | C11: ICRA AAA | D11: 3000000 | E11: 3127.37 | F11: 0.0874 | G11: 0.076611
A12: 7.48% IRFC NCD RED 13-08-2029** | B12: INE053F07BU3 | C12: CRISIL AAA | D12: 3000000 | E12: 2976.67 | F12: 0.0832 | G12: 0.07625
A13: 7.41% IOC NCD RED 22-10-2029** | B13: INE242A08437 | C13: FITCH AAA | D13: 3000000 | E13: 2961.18 | F13: 0.0828 | G13: 0.07655
A14: 8.3% NTPC LTD NCD RED 15-01-2029** | B14: INE733E07KJ7 | C14: CRISIL AAA | D14: 2500000 | E14: 2584.09 | F14: 0.0722 | G14: 0.0759
A15: 8.85% REC LTD. NCD RED 16-04-2029** | B15: INE020B08BQ7 | C15: CRISIL AAA | D15: 1850000 | E15: 1956 | F15: 0.0547 | G15: 0.07675
A16: 7.03% HPCL NCD RED 12-04-2030** | B16: INE094A08069 | C16: CRISIL AAA | D16: 1990000 | E16: 1918.58 | F16: 0.0536 | G16: 0.076724
A17: 7.64% FOOD CORP GOI GRNT NCD 12-12-2029** | B17: INE861G08050 | C17: CRISIL AAA(CE) | D17: 1900000 | E17: 1896.42 | F17: 0.053 | G17: 0.0767
A18: 7.49% NHAI NCD RED 01-08-2029** | B18: INE906B07HG7 | C18: CRISIL AAA | D18: 1300000 | E18: 1289.34 | F18: 0.036 | G18: 0.0764
A19: 8.83% EXIM BK OF INDIA NCD RED 03-11-29** | B19: INE514E08EE3 | C19: CRISIL AAA | D19: 1000000 | E19: 1063.3 | F19: 0.0297 | G19: 0.0763
A20: 8.13% NUCLEAR POWER CORP NCD 28-03-2029** | B20: INE206D08386 | C20: CRISIL AAA | D20: 1000000 | E20: 1030.74 | F20: 0.0288 | G20: 0.076553
A21: 8.12% NHPC NCD GOI SERVICED 22-03-2029** | B21: INE848E08136 | C21: CARE AAA | D21: 1000000 | E21: 1030.67 | F21: 0.0288 | G21: 0.076503
A22: 8.27% NHAI NCD RED 28-03-2029** | B22: INE906B07GP0 | C22: CRISIL AAA | D22: 1000000 | E22: 1030.26 | F22: 0.0288 | G22: 0.0764
... A32: 8.7% LIC HOUS FIN NCD RED 23-03-2029** | B32: INE115A07OB4 | C32: CRISIL AAA | D32: 10000 | E32: 10.35 | F32: 0.0003 | G32: 0.0796
A33: Sub Total | E33: 28859 | F33: 0.8064
A35: Government Securities
A36: 7.10% GOVT OF INDIA RED 18-04-2029 | B36: IN0020220011 | C36: SOVEREIGN | D36: 5000000 | E36: 4916.79 | F36: 0.1374 | G36: 0.07428
A37: Sub Total | E37: 4916.79 | F37: 0.1374
A39: (b)Privately Placed/Unlisted
A40: Sub Total | E40: NIL | F40: NIL
A42: (c)Securitised Debt Instruments
A43: Sub Total | E43: NIL | F43: NIL
A45: TOTAL | E45: 33775.79 | F45: 0.9438
A48: TREPS / Reverse Repo
A49: Clearing Corporation of India Ltd. | E49: 877.85 | F49: 0.0245 | G49: 0.061074
A50: Sub Total | E50: 877.85 | F50: 0.0245
A52: TOTAL | E52: 877.85 | F52: 0.0245
A53: Accrued Interest | E53: 1026.7213 | F53: 0.028692
A54: Net Receivables/(Payables) | E54: 103.46868 | F54: 0.003008 | G54: 0.061074
A55: GRAND TOTAL | E55: 35783.83 | F55: 1
A57: **Non Traded Security
A60: Notes:
A61: 1. Security in default beyond its maturiy date | B61: NIL
A62: 2. NAV at the beginning of the period (Rs. per unit)
A63: Plan /option (Face Value 10) | B63: As on | C63: As on
...

Sheet EDCG27
A1: PORTFOLIO STATEMENT OF EDELWEISS CRISIL IBX 50:50 GILT PLUS SDL JUNE 2027 INDEX FUND AS ON OCTOBER 31, 2022 | H1: =HYPERLINK("[EDEL_Portfolio Monthly Notes 31-Oct-2022.xlsx]Index!A1","Index") -> Index
A2: (An open-ended target maturity Index Fund investing in the constituents of CRISIL IBX 50:50 Gilt Plus SDL Index – June 2027. A relatively high interest)
A4: Name of the Instrument | B4: ISIN | C4: Rating/Industry | D4: Quantity | E4: Market/Fair Value(Rs. In Lacs) | F4: % to Net Assets | G4: YIELD
A7: Equity & Equity related | E7: NIL | F7: NIL
A8: Debt Instruments
A9: (a) Listed / Awaiting listing on Stock Exchanges
A10: Sub Total | E10: NIL | F10: NIL
A12: Government Securities
A13: 7.38% GOVT OF INDIA RED 20-06-2027 | B13: IN0020220037 | C13: SOVEREIGN | D13: 2000000 | E13: 1999.88 | F13: 0.4573 | G13: 0.073781
A14: Sub Total | E14: 1999.88 | F14: 0.4573
A16: State Development Loan
A17: 7.16% TAMILNADU SDL RED 11-01-2027 | B17: IN3120160178 | C17: SOVEREIGN | D17: 2000000 | E17: 1977.28 | F17: 0.4522 | G17: 0.074761
A18: 7.67% UTTAR PRADESH SDL 12-04-2027 | B18: IN3320170019 | C18: SOVEREIGN | D18: 200000 | E18: 200.94 | F18: 0.046 | G18: 0.075416
A19: Sub Total | E19: 2178.22 | F19: 0.4982
A22: (b)Privately Placed/Unlisted
A23: Sub Total | E23: NIL | F23: NIL
A25: (c)Securitised Debt Instruments
A26: Sub Total | E26: NIL | F26: NIL
A28: TOTAL | E28: 4178.1 | F28: 0.9555
A31: TREPS / Reverse Repo
A32: Clearing Corporation of India Ltd. | E32: 229.96 | F32: 0.0526 | G32: 0.061074
A33: Sub Total | E33: 229.96 | F33: 0.0526
A35: TOTAL | E35: 229.96 | F35: 0.0526
A36: Accrued Interest | E36: 98.313645 | F36: 0.022482
A37: Net Receivables/(Payables) | E37: -133.54365 | F37: -0.030582 | G37: 0.061074
A38: GRAND TOTAL | E38: 4372.83 | F38: 1
A40: **Non Traded Security
A43: Notes:
A44: 1. Security in default beyond its maturiy date | B44: NIL
A45: 2. NAV at the beginning of the period (Rs. per unit)
A46: Plan /option (Face Value 10) | B46: As on | C46: As on
B47: 44834 | C47: 44865
A48: Direct Plan Growth Option | B48: ^ | C48: 10.0244
A49: Direct Plan IDCW Option | B49: ^ | C49: 10.0244
A50: Regular Plan Growth Option | B50: ^ | C50: 10.0234
A51: Regular Plan IDCW Option | B51: ^ | C51: 10.0234
A52: ^ There were no investors in this option.
A54: 3. Total Dividend (Net) declared during the month | B54: NIL
A55: 4. Bonus was declared during the month | B55: NIL
A56: 5. Investment in Repo of Corporate Debt Securities during the month ended October 31, 2022 | B56: NIL
...

Sheet EDCG37
A1: PORTFOLIO STATEMENT OF EDELWEISS CRISIL IBX 50:50 GILT PLUS SDL APRIL 2037 INDEX FUND AS ON OCTOBER 31, 2022 | H1: =HYPERLINK("[EDEL_Portfolio Monthly Notes 31-Oct-2022.xlsx]Index!A1","Index") -> Index
A2: (An open-ended target maturity Index Fund investing in the constituents of CRISIL IBX 50:50 Gilt Plus SDL Index – April 2037. A relatively high interes)
A4: Name of the Instrument | B4: ISIN | C4: Rating/Industry | D4: Quantity | E4: Market/Fair Value(Rs. In Lacs) | F4: % to Net Assets | G4: YIELD
A7: Equity & Equity related | E7: NIL | F7: NIL
A8: Debt Instruments
A9: (a) Listed / Awaiting listing on Stock Exchanges
A10: Sub Total | E10: NIL | F10: NIL
A12: State Development Loan
A13: 7.89% TELANGANA SDL RED 27-10-2036 | B13: IN4520220224 | C13: SOVEREIGN | D13: 3500000 | E13: 3513.65 | F13: 0.5761 | G13: 0.078434
A14: 7.83% TELANGANA SDL RED 04-10-2036 | B14: IN4520220216 | C14: SOVEREIGN | D14: 2500000 | E14: 2501.28 | F14: 0.4101 | G14: 0.078228
A15: Sub Total | E15: 6014.93 | F15: 0.9862
A18: (b)Privately Placed/Unlisted
A19: Sub Total | E19: NIL | F19: NIL
A21: (c)Securitised Debt Instruments
A22: Sub Total | E22: NIL | F22: NIL
A24: TOTAL | E24: 6014.93 | F24: 0.9862
A27: TREPS / Reverse Repo
A28: Clearing Corporation of India Ltd. | E28: 79.99 | F28: 0.0131 | G28: 0.061074
A29: Sub Total | E29: 79.99 | F29: 0.0131
A31: TOTAL | E31: 79.99 | F31: 0.0131
A32: Accrued Interest | E32: 17.762967 | F32: 0.002912
A33: Net Receivables/(Payables) | E33: -13.642967 | F33: -0.002212 | G33: 0.061074
A34: GRAND TOTAL | E34: 6099.04 | F34: 1
A36: **Non Traded Security
A39: Notes:
A40: 1. Security in default beyond its maturiy date | B40: NIL
A41: 2. NAV at the beginning of the period (Rs. per unit)
A42: Plan /option (Face Value 10) | B42: As on | C42: As on
B43: 44834 | C43: 44865
A44: Direct Plan Growth Option | B44: ^ | C44: 10.0545
A45: Direct Plan IDCW Option | B45: ^ | C45: 10.0544
A46: Regular Plan Growth Option | B46: ^ | C46: 10.0532
A47: Regular Plan IDCW Option | B47: ^ | C47: 10.0531
A48: ^ There were no investors in this option.
A50: 3. Total Dividend (Net) declared during the month | B50: NIL
A51: 4. Bonus was declared during the month | B51: NIL
A52: 5. Investment in Repo of Corporate Debt Securities during the month ended October 31, 2022 | B52: NIL
A53: 6. Investment in foreign securities/ADRs/GDRs at the end of the month | B53: NIL
A54: 7. Average Portfolio Maturity | B54: 13.818954
A55: 8. Total gross exposure to derivative instruments (excluding reversed positions) at the end of the month (Rs. in Lakhs) | B55: NIL
...

Sheet EDCPSF
A1: PORTFOLIO STATEMENT OF EDELWEISS CRL PSU PL SDL 50:50 OCT-25 FD AS ON OCTOBER 31, 2022 | H1: =HYPERLINK("[EDEL_Portfolio Monthly Notes 31-Oct-2022.xlsx]Index!A1","Index") -> Index
A2: (An open-ended target maturity Index Fund investing in the constituents of CRISIL [IBX] 50:50 PSU + SDL Index – October 2025. A moderate interest rate risk and relatively low credit risk.)
A4: Name of the Instrument | B4: ISIN | C4: Rating/Industry | D4: Quantity | E4: Market/Fair Value(Rs. In Lacs) | F4: % to Net Assets | G4: YIELD
A7: Equity & Equity related | E7: NIL | F7: NIL
A9: Debt Instruments
A10: (a)Listed / Awaiting listing on stock Exchanges
A11: 7.20% EXIM NCD RED 05-06-2025** | B11: INE514E08FY8 | C11: CRISIL AAA | D11: 6000000 | E11: 5967.39 | F11: 0.0714 | G11: 0.0741
A12: 8.11% REC LTD NCD 07-10-2025 SR136** | B12: INE020B08963 | C12: CRISIL AAA | D12: 5000000 | E12: 5071.96 | F12: 0.0607 | G12: 0.0755
A13: 7.25% SIDBI NCD RED 31-07-2025** | B13: INE556F08KA6 | C13: ICRA AAA | D13: 5000000 | E13: 4961.99 | F13: 0.0594 | G13: 0.07545
A14: 5.7% NABARD NCD RED SR 22D 31-07-2025** | B14: INE261F08DK7 | C14: CRISIL AAA | D14: 4500000 | E14: 4299.58 | F14: 0.0514 | G14: 0.0754
A15: 7.34% NHB LTD NCD RED 07-08-2025** | B15: INE557F08FN7 | C15: CRISIL AAA | D15: 3500000 | E15: 3489.94 | F15: 0.0418 | G15: 0.07445
A16: 7.50% NHPC LTD SR Y STR A NCD 07-10-2025** | B16: INE848E07AO4 | C16: ICRA AAA | D16: 2500000 | E16: 2505.32 | F16: 0.03 | G16: 0.0741
A17: 7.20% NABARD NCD RED 23-09-2025 | B17: INE261F08DR2 | C17: ICRA AAA | D17: 2500000 | E17: 2477.77 | F17: 0.0296 | G17: 0.0754
A18: 6.50% POWER FIN CORP NCD RED 17-09-2025** | B18: INE134E08LD7 | C18: CRISIL AAA | D18: 2500000 | E18: 2433.69 | F18: 0.0291 | G18: 0.0755
A19: 7.12% HPCL NCD RED 30-07-2025** | B19: INE094A08127 | C19: CRISIL AAA | D19: 2000000 | E19: 1981.7 | F19: 0.0237 | G19: 0.074825
A20: 7.17% POWER FIN COR NCD SR 202B 22-05-25** | B20: INE134E08KT5 | C20: CRISIL AAA | D20: 2000000 | E20: 1981.64 | F20: 0.0237 | G20: 0.0755
A21: 7.15% SIDBI NCD RED 02-06-2025** | B21: INE556F08JY8 | C21: ICRA AAA | D21: 1000000 | E21: 990.39 | F21: 0.0119 | G21: 0.07545
A22: 8.75% REC LTD NCD RED 12-07-2025** | B22: INE020B08443 | C22: CRISIL AAA | D22: 500000 | E22: 513.81 | F22: 0.0061 | G22: 0.0755
... A24: 7.30% NMDC LTD SR I NCD RED 28-08-2025** | B24: INE584A08010 | C24: ICRA AAA | D24: 500000 | E24: 494.84 | F24: 0.0059 | G24: 0.07705
A25: Sub Total | E25: 37680.33 | F25: 0.4508
A27: Government Securities
A28: 5.22% GOVT OF INDIA RED 15-06-2025 | B28: IN0020200112 | C28: SOVEREIGN | D28: 3500000 | E28: 3337.82 | F28: 0.0399 | G28: 0.071867
A29: Sub Total | E29: 3337.82 | F29: 0.0399
A30: State Development Loan
A31: 8.20% GUJARAT SDL RED 24-06-2025 | B31: IN1520150021 | C31: SOVEREIGN | D31: 5000000 | E31: 5090.73 | F31: 0.0609 | G31: 0.074258
A32: 8.31% ANDHRA PRADESH SDL RED 29-07-2025 | B32: IN1020150042 | C32: SOVEREIGN | D32: 3500000 | E32: 3570.92 | F32: 0.0427 | G32: 0.07472
A33: 8.31% UTTAR PRADESH SDL 29-07-2025 | B33: IN3320150250 | C33: SOVEREIGN | D33: 2500000 | E33: 2549.86 | F33: 0.0305 | G33: 0.074848
A34: 8.27% KERALA SDL RED 12-08-2025 | B34: IN2020150073 | C34: SOVEREIGN | D34: 2500000 | E34: 2549.77 | F34: 0.0305 | G34: 0.074565
A35: 8.30% JHARKHAND SDL RED 29-07-2025 | B35: IN3720150017 | C35: SOVEREIGN | D35: 2500000 | E35: 2548.53 | F35: 0.0305 | G35: 0.074965
A36: 8.21% WEST BENGAL SDL RED 24-06-2025 | B36: IN3420150036 | C36: SOVEREIGN | D36: 2500000 | E36: 2543.28 | F36: 0.0304 | G36: 0.074705
A37: 7.99% MAHARASHTRA SDL RED 28-10-2025 | B37: IN2220150113 | C37: SOVEREIGN | D37: 2500000 | E37: 2536.51 | F37: 0.0304 | G37: 0.074362
A38: 7.97% TAMIL NADU SDL RED 14-10-2025 | B38: IN3120150112 | C38: SOVEREIGN | D38: 2500000 | E38: 2533.5 | F38: 0.0303 | G38: 0.074537
A39: 7.89% GUJARAT SDL RED 15-05-2025 | B39: IN1520190043 | C39: SOVEREIGN | D39: 2500000 | E39: 2526.89 | F39: 0.0302 | G39: 0.074152
A40: 8.24% KERALA SDL RED 13-05-2025 | B40: IN2020150032 | C40: SOVEREIGN | D40: 2000000 | E40: 2036.24 | F40: 0.0244 | G40: 0.0744
A41: 8.22% TAMIL NADU SDL RED 13-05-2025 | B41: IN3120150039 | C41: SOVEREIGN | D41: 2000000 | E41: 2035.78 | F41: 0.0244 | G41: 0.074302
A42: 8.20% RAJASTHAN SDL RED 24-06-2025 | B42: IN2920150157 | C42: SOVEREIGN | D42: 2000000 | E42: 2033.89 | F42: 0.0243 | G42: 0.074759
... A50: 8% TAMIL NADU SDL RED 28-10-2025 | B50: IN3120150120 | C50: SOVEREIGN | D50: 500000 | E50: 507.2 | F50: 0.0061 | G50: 0.074537
A51: Sub Total | E51: 40135.6 | F51: 0.4803
A54: (b)Privately Placed/Unlisted
A55: Sub Total | E55: NIL | F55: NIL
...

Sheet EDFF23
A1: PORTFOLIO STATEMENT OF BHARAT BOND FOF – APRIL 2023 AS ON OCTOBER 31, 2022 | H1: =HYPERLINK("[EDEL_Portfolio Monthly Notes 31-Oct-2022.xlsx]Index!A1","Index") -> Index
A2: (An open-ended Target Maturity fund of funds scheme investing in units of BHARAT Bond ETF – April 2023)
A4: Name of the Instrument | B4: ISIN | C4: Rating/Industry | D4: Quantity | E4: Market/Fair Value(Rs. In Lacs) | F4: % to Net Assets | G4: YIELD
A7: Equity & Equity related | E7: NIL | F7: NIL
A10: Investment in Mutual fund
A11: BHARAT BOND ETF-APRIL 2023-GROWTH | B11: INF754K01KN4 | D11: 27573010 | E11: 329431.29 | F11: 0.9846
A12: Sub Total | E12: 329431.29 | F12: 0.9846
A14: TOTAL | E14: 329431.29 | F14: 0.9846
A16: TREPS / Reverse Repo
A17: Clearing Corporation of India Ltd. | E17: 2534.58 | F17: 0.0076 | G17: 0.061074
A18: Sub Total | E18: 2534.58 | F18: 0.0076
A20: TOTAL | E20: 2534.58 | F20: 0.0076
A21: Accrued Interest | E21: 0.4241005 | F21: 1e-06
A22: Net Receivables/(Payables) | E22: 2627.5659 | F22: 0.007799 | G22: 0.061074
A23: GRAND TOTAL | E23: 334593.86 | F23: 1
A28: Notes:
A29: 1. Security in default beyond its maturiy date | B29: NIL
A30: 2. NAV at the beginning of the period (Rs. per unit)
A31: Plan /option (Face Value 10) | B31: As on | C31: As on
B32: 44834 | C32: 44865
A33: Direct Plan Growth Option | B33: 11.8681 | C33: 11.9225
A34: Direct Plan IDCW Option | B34: 11.8681 | C34: 11.9225
A35: Regular Plan Growth Option | B35: 11.8681 | C35: 11.9225
A36: Regular Plan IDCW Option | B36: 11.8681 | C36: 11.9225
A38: 3. Total Dividend (Net) declared during the month | B38: NIL
A39: 4. Bonus was declared during the month | B39: NIL
A40: 5. Investment in Repo of Corporate Debt Securities during the month ended October 31, 2022 | B40: NIL
A41: 6. Investment in foreign securities/ADRs/GDRs at the end of the month | B41: NIL
A42: 7. Average Portfolio Maturity | B42: 0.41636783
A43: 8. Total gross exposure to derivative instruments (excluding reversed positions) at the end of the month (Rs. in Lakhs) | B43: NIL
A44: 9. Margin Deposits includes Margin money placed on derivatives other than margin money placed with bank | B44: NIL
A45: 10. Value of investment made by other schemes under same management (Rs. In Lakhs) | B45: NIL
A46: 11. Number of instance of deviation In valuation of securities | B46: NIL
A47: 12. Total value and percentage of illiquid equity shares / securities | B47: NIL
A50: Scheme Name | B50: Risk- O - Meter | C50: Benchmark of the Scheme | D50: Benchmark Risk-o-meter
A51: BHARAT Bond FOF - April 2023 | C51: NIFTY BHARAT Bond Index - April 2023

Sheet EDFF25
A1: PORTFOLIO STATEMENT OF BHARAT BOND FOF – APRIL 2025 AS ON OCTOBER 31, 2022 | H1: =HYPERLINK("[EDEL_Portfolio Monthly Notes 31-Oct-2022.xlsx]Index!A1","Index") -> Index
A2: (An open-ended Target Maturity fund of funds scheme investing in units of BHARAT Bond ETF – April 2025)
A4: Name of the Instrument | B4: ISIN | C4: Rating/Industry | D4: Quantity | E4: Market/Fair Value(Rs. In Lacs) | F4: % to Net Assets | G4: YIELD
A7: Equity & Equity related | E7: NIL | F7: NIL
A10: Investment in Mutual fund
A11: BHARAT BOND ETF-APRIL 2025-GROWTH | B11: INF754K01LD3 | D11: 36438149 | E11: 394173.32 | F11: 0.9902
A12: Sub Total | E12: 394173.32 | F12: 0.9902
A14: TOTAL | E14: 394173.32 | F14: 0.9902
A16: TREPS / Reverse Repo
A17: Clearing Corporation of India Ltd. | E17: 393.93 | F17: 0.001 | G17: 0.061074
A18: Sub Total | E18: 393.93 | F18: 0.001
A20: TOTAL | E20: 393.93 | F20: 0.001
A21: Accrued Interest | E21: 0.0659154 | F21: 0
A22: Net Receivables/(Payables) | E22: 3520.0641 | F22: 0.0088 | G22: 0.061074
A23: GRAND TOTAL | E23: 398087.38 | F23: 1
A28: Notes:
A29: 1. Security in default beyond its maturiy date | B29: NIL
A30: 2. NAV at the beginning of the period (Rs. per unit)
A31: Plan /option (Face Value 10) | B31: As on | C31: As on
B32: 44834 | C32: 44865
A33: Direct Plan Growth Option | B33: 10.7499 | C33: 10.7952
A34: Direct Plan IDCW Option | B34: 10.7499 | C34: 10.7952
A35: Regular Plan Growth Option | B35: 10.7499 | C35: 10.7952
A36: Regular Plan IDCW Option | B36: 10.7499 | C36: 10.7952
A38: 3. Total Dividend (Net) declared during the month | B38: NIL
A39: 4. Bonus was declared during the month | B39: NIL
A40: 5. Investment in Repo of Corporate Debt Securities during the month ended October 31, 2022 | B40: NIL
A41: 6. Investment in foreign securities/ADRs/GDRs at the end of the month | B41: NIL
A42: 7. Average Portfolio Maturity | B42: 2.2910529
A43: 8. Total gross exposure to derivative instruments (excluding reversed positions) at the end of the month (Rs. in Lakhs) | B43: NIL
A44: 9. Margin Deposits includes Margin money placed on derivatives other than margin money placed with bank | B44: NIL
A45: 10. Value of investment made by other schemes under same management (Rs. In Lakhs) | B45: NIL
A46: 11. Number of instance of deviation In valuation of securities | B46: NIL
A47: 12. Total value and percentage of illiquid equity shares / securities | B47: NIL
A49: Scheme Name | B49: Risk- O - Meter | C49: Benchmark of the Scheme | D49: Benchmark Risk-o-meter
A50: BHARAT Bond FOF - April 2025 | C50: Nifty BHARAT Bond Index – April 2025

Sheet EDFF30
A1: PORTFOLIO STATEMENT OF BHARAT BOND FOF – APRIL 2030 AS ON OCTOBER 31, 2022 | H1: =HYPERLINK("[EDEL_Portfolio Monthly Notes 31-Oct-2022.xlsx]Index!A1","Index") -> Index
A2: (An open-ended Target Maturity fund of funds scheme investing in units of BHARAT Bond ETF – April 2030)
A4: Name of the Instrument | B4: ISIN | C4: Rating/Industry | D4: Quantity | E4: Market/Fair Value(Rs. In Lacs) | F4: % to Net Assets | G4: YIELD
A7: Equity & Equity related | E7: NIL | F7: NIL
A10: Investment in Mutual fund
A11: BHARAT BOND ETF-APRIL 2030-GROWTH | B11: INF754K01KO2 | D11: 38159325 | E11: 461517.96 | F11: 0.996
A12: Sub Total | E12: 461517.96 | F12: 0.996
A14: TOTAL | E14: 461517.96 | F14: 0.996
A16: TREPS / Reverse Repo
A17: Clearing Corporation of India Ltd. | E17: 2394.6 | F17: 0.0052 | G17: 0.061074
A18: Sub Total | E18: 2394.6 | F18: 0.0052
A20: TOTAL | E20: 2394.6 | F20: 0.0052
A21: Accrued Interest | E21: 0.4006788 | F21: 0
A22: Net Receivables/(Payables) | E22: -528.08068 | F22: -0.0012 | G22: 0.061074
A23: GRAND TOTAL | E23: 463384.88 | F23: 1
A28: Notes:
A29: 1. Security in default beyond its maturiy date | B29: NIL
A30: 2. NAV at the beginning of the period (Rs. per unit)
A31: Plan /option (Face Value 10) | B31: As on | C31: As on
B32: 44834 | C32: 44865
A33: Direct Plan Growth Option | B33: 12.0473 | C33: 12.0712
A34: Direct Plan IDCW Option | B34: 12.0473 | C34: 12.0712
A35: Regular Plan Growth Option | B35: 12.0473 | C35: 12.0712
A36: Regular Plan IDCW Option | B36: 12.0473 | C36: 12.0712
A38: 3. Total Dividend (Net) declared during the month | B38: NIL
A39: 4. Bonus was declared during the month | B39: NIL
A40: 5. Investment in Repo of Corporate Debt Securities during the month ended October 31, 2022 | B40: NIL
A41: 6. Investment in foreign securities/ADRs/GDRs at the end of the month | B41: NIL
A42: 7. Average Portfolio Maturity | B42: 7.0704069
A43: 8. Total gross exposure to derivative instruments (excluding reversed positions) at the end of the month (Rs. in Lakhs) | B43: NIL
A44: 9. Margin Deposits includes Margin money placed on derivatives other than margin money placed with bank | B44: NIL
A45: 10. Value of investment made by other schemes under same management (Rs. In Lakhs) | B45: NIL
A46: 11. Number of instance of deviation In valuation of securities | B46: NIL
A47: 12. Total value and percentage of illiquid equity shares / securities | B47: NIL
A50: Scheme Name | B50: Risk- O - Meter | C50: Benchmark of the Scheme | D50: Benchmark Risk-o-meter
A51: BHARAT Bond FOF - April 2030 | C51: NIFTY BHARAT Bond Index - April 2030

Sheet EDFF31
A1: PORTFOLIO STATEMENT OF BHARAT BOND FOF – APRIL 2031 AS ON OCTOBER 31, 2022 | H1: =HYPERLINK("[EDEL_Portfolio Monthly Notes 31-Oct-2022.xlsx]Index!A1","Index") -> Index
A2: (An open-ended Target Maturity fund of funds scheme investing in units of BHARAT Bond ETF – April 2031)
A4: Name of the Instrument | B4: ISIN | C4: Rating/Industry | D4: Quantity | E4: Market/Fair Value(Rs. In Lacs) | F4: % to Net Assets | G4: YIELD
A7: Equity & Equity related | E7: NIL | F7: NIL
A10: Investment in Mutual fund
A11: BHARAT BOND ETF-APRIL 2031-GROWTH | B11: INF754K01LE1 | D11: 30201692 | E11: 326244.72 | F11: 0.9968
A12: Sub Total | E12: 326244.72 | F12: 0.9968
A14: TOTAL | E14: 326244.72 | F14: 0.9968
A16: TREPS / Reverse Repo
A17: Clearing Corporation of India Ltd. | E17: 1497.75 | F17: 0.0046 | G17: 0.061074
A18: Sub Total | E18: 1497.75 | F18: 0.0046
A20: TOTAL | E20: 1497.75 | F20: 0.0046
A21: Accrued Interest | E21: 0.2506125 | F21: 0
A22: Net Receivables/(Payables) | E22: -446.37061 | F22: -0.0014 | G22: 0.061074
A23: GRAND TOTAL | E23: 327296.35 | F23: 1
A28: Notes:
A29: 1. Security in default beyond its maturiy date | B29: NIL
A30: 2. NAV at the beginning of the period (Rs. per unit)
A31: Plan /option (Face Value 10) | B31: As on | C31: As on
B32: 44834 | C32: 44865
A33: Direct Plan Growth Option | B33: 10.7353 | C33: 10.7853
A34: Direct Plan IDCW Option | B34: 10.7353 | C34: 10.7853
A35: Regular Plan Growth Option | B35: 10.7353 | C35: 10.7853
A36: Regular Plan IDCW Option | B36: 10.7353 | C36: 10.7853
A38: 3. Total Dividend (Net) declared during the month | B38: NIL
A39: 4. Bonus was declared during the month | B39: NIL
A40: 5. Investment in Repo of Corporate Debt Securities during the month ended October 31, 2022 | B40: NIL
A41: 6. Investment in foreign securities/ADRs/GDRs at the end of the month | B41: NIL
A42: 7. Average Portfolio Maturity | B42: 8.1143292
A43: 8. Total gross exposure to derivative instruments (excluding reversed positions) at the end of the month (Rs. in Lakhs) | B43: NIL
A44: 9. Margin Deposits includes Margin money placed on derivatives other than margin money placed with bank | B44: NIL
A45: 10. Value of investment made by other schemes under same management (Rs. In Lakhs) | B45: NIL
A46: 11. Number of instance of deviation In valuation of securities | B46: NIL
A47: 12. Total value and percentage of illiquid equity shares / securities | B47: NIL
A49: Scheme Name | B49: Risk- O - Meter | C49: Benchmark of the Scheme | D49: Benchmark Risk-o-meter
A50: BHARAT Bond FOF - April 2031 | C50: NIFTY BHARAT Bond Index - April 2031

Sheet EDFF32
A1: PORTFOLIO STATEMENT OF BHARAT BOND FOF – APRIL 2032 AS ON OCTOBER 31, 2022 | H1: =HYPERLINK("[EDEL_Portfolio Monthly Notes 31-Oct-2022.xlsx]Index!A1","Index") -> Index
A2: (An open-ended Target Maturity fund of funds scheme investing in units of BHARAT Bond ETF – April 2032)
A4: Name of the Instrument | B4: ISIN | C4: Rating/Industry | D4: Quantity | E4: Market/Fair Value(Rs. In Lacs) | F4: % to Net Assets | G4: YIELD
A7: Equity & Equity related | E7: NIL | F7: NIL
A10: Investment in Mutual fund
A11: BHARAT BOND ETF–APRIL 2032-GROWTH | B11: INF754K01OB1 | D11: 22003848 | E11: 223094.81 | F11: 0.9967
A12: Sub Total | E12: 223094.81 | F12: 0.9967
A14: TOTAL | E14: 223094.81 | F14: 0.9967
A16: TREPS / Reverse Repo
A17: Clearing Corporation of India Ltd. | E17: 941.84 | F17: 0.0042 | G17: 0.061074
A18: Sub Total | E18: 941.84 | F18: 0.0042
A20: TOTAL | E20: 941.84 | F20: 0.0042
A21: Accrued Interest | E21: 0.1575947 | F21: 0
A22: Net Receivables/(Payables) | E22: -212.64759 | F22: -0.0009 | G22: 0.061074
A23: GRAND TOTAL | E23: 223824.16 | F23: 1
A28: Notes:
A29: 1. Security in default beyond its maturiy date | B29: NIL
A30: 2. NAV at the beginning of the period (Rs. per unit)
A31: Plan /option (Face Value 10) | B31: As on | C31: As on
B32: 44834 | C32: 44865
A33: Direct Plan Growth Option | B33: 10.0559 | C33: 10.1449
A34: Direct Plan IDCW Option | B34: 10.0559 | C34: 10.1449
A35: Regular Plan Growth Option | B35: 10.0559 | C35: 10.1449
A36: Regular Plan IDCW Option | B36: 10.0559 | C36: 10.1449
A38: 3. Total Dividend (Net) declared during the month | B38: NIL
A39: 4. Bonus was declared during the month | B39: NIL
A40: 5. Investment in Repo of Corporate Debt Securities during the month ended October 31, 2022 | B40: NIL
A41: 6. Investment in foreign securities/ADRs/GDRs at the end of the month | B41: NIL
A42: 7. Average Portfolio Maturity | B42: 9.2642486
A43: 8. Total gross exposure to derivative instruments (excluding reversed positions) at the end of the month (Rs. in Lakhs) | B43: NIL
A44: 9. Margin Deposits includes Margin money placed on derivatives other than margin money placed with bank | B44: NIL
A45: 10. Value of investment made by other schemes under same management (Rs. In Lakhs) | B45: NIL
A46: 11. Number of instance of deviation In valuation of securities | B46: NIL
A47: 12. Total value and percentage of illiquid equity shares / securities | B47: NIL
A50: Scheme Name | B50: Risk- O - Meter | C50: Benchmark of the Scheme | D50: Benchmark Risk-o-meter
A51: BHARAT Bond FOF - April 2032 | C51: Nifty BHARAT Bond Index – April 2032

Sheet EDGSEC
A1: PORTFOLIO STATEMENT OF EDELWEISS GOVERNMENT SECURITIES FUND AS ON OCTOBER 31, 2022 | H1: =HYPERLINK("[EDEL_Portfolio Monthly Notes 31-Oct-2022.xlsx]Index!A1","Index") -> Index
A2: (An open ended debt scheme investing in government securities across maturity)
A4: Name of the Instrument | B4: ISIN | C4: Rating/Industry | D4: Quantity | E4: Market/Fair Value(Rs. In Lacs) | F4: % to Net Assets | G4: YIELD
A7: Equity & Equity related | E7: NIL | F7: NIL
A8: Debt Instruments
A9: (a) Listed / Awaiting listing on Stock Exchanges
A10: Sub Total | E10: NIL | F10: NIL
A12: Government Securities
A13: 7.38% GOVT OF INDIA RED 20-06-2027 | B13: IN0020220037 | C13: SOVEREIGN | D13: 7000000 | E13: 6999.59 | F13: 0.61 | G13: 0.073781
A14: 7.26% GOVT OF INDIA RED 22-08-2032 | B14: IN0020220060 | C14: SOVEREIGN | D14: 2000000 | E14: 1974.02 | F14: 0.172 | G14: 0.074467
